Workbook

Sheet Operations
C3: Fron Office | D3: Back Office | E3: Ente Terzo | F3: Comunica | G3: Registro Imprese
B4: Creazione Istanza | C4: F ->> C: request_cui | D4: B ->> C: add_permit_document | F4: CU ->> F: fo-portal-ref
C5: F ->> B | F ->> CU: send_instance | D5: B ->> C: update_times | F5: CU ->> F: instance/{cui_uuid}/document/{resource_id}
C6: F ->> B: notify_receipt | D6: B ->> F: instance/{cui_uuid}/document/{resource_id} | F6: CU ->> F: notify_receipt
B7: Correzione Istanza | C7: F ->> B: send_instance_updated_documents | D7: B ->> F: request_correction
D8: B ->> C: update_times
D9: B ->> C: UpdateInstancesAndTimes
D10: B ->> F: instance/{cui_uuid}/document/{resource_id}
D11: B ->> C: revoke_permit_document
D12: B ->> F: notify
B13: Richiesta Pareri | D13: B ->> E: send_instance | E13: E ->> C: instance_descriptor
E14: E ->> B: instance/{cui_uuid}/document/{resource_id}
B15: Conformazione | C15: F ->> B: instance/{cui_uuid}/document/{resource_id} | D15: B ->> E | B ->> F: instance/{cui_uuid}/document/{resource_id} | E15: E ->> B: request_conformation
C16: B ->> F: notify | D16: B ->> E: notify | E16: E ->> B: instance/{cui_uuid}/document/{resource_id}
C17: F ->> B: send_instance_updated_documents | D17: B ->> F: request_conformation
D18: B ->> C: update_times
D19: B ->> C: update_attachments_and_times
D20: B ->> E: send_instance_updated_documents
B21: Integrazione | C21: F ->> B: instance/{cui_uuid}/document/{resource_id} | D21: B ->> E | B ->> F: instance/{cui_uuid}/document/{resource_id} | E21: E ->> B: request_integration
C22: F ->> B: send_instance_updated_documents | D22: B ->> E | B ->> F: notify | E22: E ->> B: instance/{cui_uuid}/document/{resource_id}
D23: B ->> F: request_integration
D24: B ->> C: update_times
D25: B ->> C: update_attachments_and_times
D26: B ->> E: send_instance_updated_documents
B27: CDSA | C27: F ->> B: instance/{cui_uuid}/document/{resource_id} | D27: B ->> C: update_times | E27: E ->> B: notify
C28: F ->> B: notify | D28: B ->> F | B ->> E: notify | E28: B ->> E: instance/{cui_uuid}/document/{resource_id}
D29: B ->> F: instance/{cui_uuid}/document/{resource_id}
B30: CDSS | C30: F ->> B: instance/{cui_uuid}/document/{resource_id} | D30: B ->> C: update_times | E30: E ->> B: instance/{cui_uuid}/document/{resource_id}
D31: B ->> F | B ->> E: notify | E31: E ->> B : request_cdss
D32: B ->> E: send_instance
D33: B ->> E | B ->> F: cdss_resolution_forward
B34: CERS | D34: B ->> C: update_times | E34: E ->> C: instance_descriptor | G34: RI ->> C: request_cui
D35: B ->> RI: instance/{cui_uuid}/document/{resource_id} | E35: E ->> B: instance/{cui_uuid}/document/{resource_id} | G35: RI ->> B: send_instance
D36: B ->> E: send_instance | G36: RI ->> B: notify_receipt
D37: B ->> E: notify
B38: ZES | D38: BOZES ->> BOADSP | BOADSP ->> BOZES: retry
D39: BOZES ->> BOADSP: transfer_instance
D40: BOZES ->> BOADSP: instance/{cui_uuid}/document/{resource_id}
D41: BOADSP ->> BOZES: notify
B42: ET RICORSIVO | D42: B ->> E: send_instance | E42: E ->> E: send_instance
...

Sheet bo_to_fo
B1: Operation | C1: Check
B2: notify_receipt | C2: {=IF(SUMPRODUCT(--(IFERROR(MID(SUBSTITUTE(SUBSTITUTE(Operations!$C$4:$C$67," ",""),CHAR(160),""),FIND(":",SUBSTITUTE(SUBSTITUTE(Operations!$C$4:$C$67," ",""),CHAR(160),""))+1,999),"")=SUBSTITUTE(SUBSTITUTE($B2," ",""),CHAR(160),"")),--ISNUMBER(SEARCH("|F->>B|","|"&IFERROR(LEFT(SUBSTITUTE(SUBSTITUTE(Operations!$C$4:$C$67," ",""),CHAR(160),""),FIND(":",SUBSTITUTE(SUBSTITUTE(Operations!$C$4:$C$67," ",""),CHAR(160),""))-1),"")&"|")))>0,"trovato","non trovato")} -> trovato
B3: notify | C3: {=IF(SUMPRODUCT(--(IFERROR(MID(SUBSTITUTE(SUBSTITUTE(Operations!$C$4:$C$67," ",""),CHAR(160),""),FIND(":",SUBSTITUTE(SUBSTITUTE(Operations!$C$4:$C$67," ",""),CHAR(160),""))+1,999),"")=SUBSTITUTE(SUBSTITUTE($B3," ",""),CHAR(160),"")),--ISNUMBER(SEARCH("|F->>B|","|"&IFERROR(LEFT(SUBSTITUTE(SUBSTITUTE(Operations!$C$4:$C$67," ",""),CHAR(160),""),FIND(":",SUBSTITUTE(SUBSTITUTE(Operations!$C$4:$C$67," ",""),CHAR(160),""))-1),"")&"|")))>0,"trovato","non trovato")} -> trovato
B4: cancel_instance | C4: {=IF(SUMPRODUCT(--(IFERROR(MID(SUBSTITUTE(SUBSTITUTE(Operations!$C$4:$C$67," ",""),CHAR(160),""),FIND(":",SUBSTITUTE(SUBSTITUTE(Operations!$C$4:$C$67," ",""),CHAR(160),""))+1,999),"")=SUBSTITUTE(SUBSTITUTE($B4," ",""),CHAR(160),"")),--ISNUMBER(SEARCH("|F->>B|","|"&IFERROR(LEFT(SUBSTITUTE(SUBSTITUTE(Operations!$C$4:$C$67," ",""),CHAR(160),""),FIND(":",SUBSTITUTE(SUBSTITUTE(Operations!$C$4:$C$67," ",""),CHAR(160),""))-1),"")&"|")))>0,"trovato","non trovato")} -> trovato
B5: retry | C5: {=IF(SUMPRODUCT(--(IFERROR(MID(SUBSTITUTE(SUBSTITUTE(Operations!$C$4:$C$67," ",""),CHAR(160),""),FIND(":",SUBSTITUTE(SUBSTITUTE(Operations!$C$4:$C$67," ",""),CHAR(160),""))+1,999),"")=SUBSTITUTE(SUBSTITUTE($B5," ",""),CHAR(160),"")),--ISNUMBER(SEARCH("|F->>B|","|"&IFERROR(LEFT(SUBSTITUTE(SUBSTITUTE(Operations!$C$4:$C$67," ",""),CHAR(160),""),FIND(":",SUBSTITUTE(SUBSTITUTE(Operations!$C$4:$C$67," ",""),CHAR(160),""))-1),"")&"|")))>0,"trovato","non trovato")} -> trovato
B6: send_instance | C6: {=IF(SUMPRODUCT(--(IFERROR(MID(SUBSTITUTE(SUBSTITUTE(Operations!$C$4:$C$67," ",""),CHAR(160),""),FIND(":",SUBSTITUTE(SUBSTITUTE(Operations!$C$4:$C$67," ",""),CHAR(160),""))+1,999),"")=SUBSTITUTE(SUBSTITUTE($B6," ",""),CHAR(160),"")),--ISNUMBER(SEARCH("|F->>B|","|"&IFERROR(LEFT(SUBSTITUTE(SUBSTITUTE(Operations!$C$4:$C$67," ",""),CHAR(160),""),FIND(":",SUBSTITUTE(SUBSTITUTE(Operations!$C$4:$C$67," ",""),CHAR(160),""))-1),"")&"|")))>0,"trovato","non trovato")} -> trovato
B7: send_instance_updated_documents | C7: {=IF(SUMPRODUCT(--(IFERROR(MID(SUBSTITUTE(SUBSTITUTE(Operations!$C$4:$C$67," ",""),CHAR(160),""),FIND(":",SUBSTITUTE(SUBSTITUTE(Operations!$C$4:$C$67," ",""),CHAR(160),""))+1,999),"")=SUBSTITUTE(SUBSTITUTE($B7," ",""),CHAR(160),"")),--ISNUMBER(SEARCH("|F->>B|","|"&IFERROR(LEFT(SUBSTITUTE(SUBSTITUTE(Operations!$C$4:$C$67," ",""),CHAR(160),""),FIND(":",SUBSTITUTE(SUBSTITUTE(Operations!$C$4:$C$67," ",""),CHAR(160),""))-1),"")&"|")))>0,"trovato","non trovato")} -> trovato
B8: delete_instance | C8: {=IF(SUMPRODUCT(--(IFERROR(MID(SUBSTITUTE(SUBSTITUTE(Operations!$C$4:$C$67," ",""),CHAR(160),""),FIND(":",SUBSTITUTE(SUBSTITUTE(Operations!$C$4:$C$67," ",""),CHAR(160),""))+1,999),"")=SUBSTITUTE(SUBSTITUTE($B8," ",""),CHAR(160),"")),--ISNUMBER(SEARCH("|F->>B|","|"&IFERROR(LEFT(SUBSTITUTE(SUBSTITUTE(Operations!$C$4:$C$67," ",""),CHAR(160),""),FIND(":",SUBSTITUTE(SUBSTITUTE(Operations!$C$4:$C$67," ",""),CHAR(160),""))-1),"")&"|")))>0,"trovato","non trovato")} -> trovato
B9: instance/{cui_uuid}/document/{resource_id} | C9: {=IF(SUMPRODUCT(--(IFERROR(MID(SUBSTITUTE(SUBSTITUTE(Operations!$C$4:$C$67," ",""),CHAR(160),""),FIND(":",SUBSTITUTE(SUBSTITUTE(Operations!$C$4:$C$67," ",""),CHAR(160),""))+1,999),"")=SUBSTITUTE(SUBSTITUTE($B9," ",""),CHAR(160),"")),--ISNUMBER(SEARCH("|F->>B|","|"&IFERROR(LEFT(SUBSTITUTE(SUBSTITUTE(Operations!$C$4:$C$67," ",""),CHAR(160),""),FIND(":",SUBSTITUTE(SUBSTITUTE(Operations!$C$4:$C$67," ",""),CHAR(160),""))-1),"")&"|")))>0,"trovato","non trovato")} -> trovato

Sheet catalogo-ssu_to_fo
B1: Operation | C1: Check
B2: request_cui | C2: {=IF(SUMPRODUCT(--(IFERROR(MID(SUBSTITUTE(SUBSTITUTE(Operations!$C$4:$C$67," ",""),CHAR(160),""),FIND(":",SUBSTITUTE(SUBSTITUTE(Operations!$C$4:$C$67," ",""),CHAR(160),""))+1,999),"")=SUBSTITUTE(SUBSTITUTE($B2," ",""),CHAR(160),"")),--ISNUMBER(SEARCH("|F->>C|","|"&IFERROR(LEFT(SUBSTITUTE(SUBSTITUTE(Operations!$C$4:$C$67," ",""),CHAR(160),""),FIND(":",SUBSTITUTE(SUBSTITUTE(Operations!$C$4:$C$67," ",""),CHAR(160),""))-1),"")&"|")))>0,"trovato","non trovato")} -> trovato
B3: audit | C3: {=IF(SUMPRODUCT(--(IFERROR(MID(SUBSTITUTE(SUBSTITUTE(Operations!$C$4:$C$67," ",""),CHAR(160),""),FIND(":",SUBSTITUTE(SUBSTITUTE(Operations!$C$4:$C$67," ",""),CHAR(160),""))+1,999),"")=SUBSTITUTE(SUBSTITUTE($B3," ",""),CHAR(160),"")),--ISNUMBER(SEARCH("|F->>C|","|"&IFERROR(LEFT(SUBSTITUTE(SUBSTITUTE(Operations!$C$4:$C$67," ",""),CHAR(160),""),FIND(":",SUBSTITUTE(SUBSTITUTE(Operations!$C$4:$C$67," ",""),CHAR(160),""))-1),"")&"|")))>0,"trovato","non trovato")} -> trovato

Sheet cu_to_fo
B1: Operation | C1: Check
B2: send_instance | C2: {=IF(SUMPRODUCT(--(IFERROR(MID(SUBSTITUTE(SUBSTITUTE(Operations!$C$4:$C$67," ",""),CHAR(160),""),FIND(":",SUBSTITUTE(SUBSTITUTE(Operations!$C$4:$C$67," ",""),CHAR(160),""))+1,999),"")=SUBSTITUTE(SUBSTITUTE($B2," ",""),CHAR(160),"")),--ISNUMBER(SEARCH("|F->>CU|","|"&IFERROR(LEFT(SUBSTITUTE(SUBSTITUTE(Operations!$C$4:$C$67," ",""),CHAR(160),""),FIND(":",SUBSTITUTE(SUBSTITUTE(Operations!$C$4:$C$67," ",""),CHAR(160),""))-1),"")&"|")))>0,"trovato","non trovato")} -> trovato
B3: retry | C3: {=IF(SUMPRODUCT(--(IFERROR(MID(SUBSTITUTE(SUBSTITUTE(Operations!$C$4:$C$67," ",""),CHAR(160),""),FIND(":",SUBSTITUTE(SUBSTITUTE(Operations!$C$4:$C$67," ",""),CHAR(160),""))+1,999),"")=SUBSTITUTE(SUBSTITUTE($B3," ",""),CHAR(160),"")),--ISNUMBER(SEARCH("|F->>CU|","|"&IFERROR(LEFT(SUBSTITUTE(SUBSTITUTE(Operations!$C$4:$C$67," ",""),CHAR(160),""),FIND(":",SUBSTITUTE(SUBSTITUTE(Operations!$C$4:$C$67," ",""),CHAR(160),""))-1),"")&"|")))>0,"trovato","non trovato")} -> trovato

Sheet fo_to_bo
B1: Operation | C1: Check
B2: retry | C2: {=IF(SUMPRODUCT(--(IFERROR(MID(SUBSTITUTE(SUBSTITUTE(Operations!$D$4:$D$67," ",""),CHAR(160),""),FIND(":",SUBSTITUTE(SUBSTITUTE(Operations!$D$4:$D$67," ",""),CHAR(160),""))+1,999),"")=SUBSTITUTE(SUBSTITUTE($B2," ",""),CHAR(160),"")),--ISNUMBER(SEARCH("|B->>F|","|"&IFERROR(LEFT(SUBSTITUTE(SUBSTITUTE(Operations!$D$4:$D$67," ",""),CHAR(160),""),FIND(":",SUBSTITUTE(SUBSTITUTE(Operations!$D$4:$D$67," ",""),CHAR(160),""))-1),"")&"|")))>0,"trovato","non trovato")} -> trovato
B3: request_correction | C3: {=IF(SUMPRODUCT(--(IFERROR(MID(SUBSTITUTE(SUBSTITUTE(Operations!$D$4:$D$67," ",""),CHAR(160),""),FIND(":",SUBSTITUTE(SUBSTITUTE(Operations!$D$4:$D$67," ",""),CHAR(160),""))+1,999),"")=SUBSTITUTE(SUBSTITUTE($B3," ",""),CHAR(160),"")),--ISNUMBER(SEARCH("|B->>F|","|"&IFERROR(LEFT(SUBSTITUTE(SUBSTITUTE(Operations!$D$4:$D$67," ",""),CHAR(160),""),FIND(":",SUBSTITUTE(SUBSTITUTE(Operations!$D$4:$D$67," ",""),CHAR(160),""))-1),"")&"|")))>0,"trovato","non trovato")} -> trovato
B4: request_integration | C4: {=IF(SUMPRODUCT(--(IFERROR(MID(SUBSTITUTE(SUBSTITUTE(Operations!$D$4:$D$67," ",""),CHAR(160),""),FIND(":",SUBSTITUTE(SUBSTITUTE(Operations!$D$4:$D$67," ",""),CHAR(160),""))+1,999),"")=SUBSTITUTE(SUBSTITUTE($B4," ",""),CHAR(160),"")),--ISNUMBER(SEARCH("|B->>F|","|"&IFERROR(LEFT(SUBSTITUTE(SUBSTITUTE(Operations!$D$4:$D$67," ",""),CHAR(160),""),FIND(":",SUBSTITUTE(SUBSTITUTE(Operations!$D$4:$D$67," ",""),CHAR(160),""))-1),"")&"|")))>0,"trovato","non trovato")} -> trovato
B5: request_conformation | C5: {=IF(SUMPRODUCT(--(IFERROR(MID(SUBSTITUTE(SUBSTITUTE(Operations!$D$4:$D$67," ",""),CHAR(160),""),FIND(":",SUBSTITUTE(SUBSTITUTE(Operations!$D$4:$D$67," ",""),CHAR(160),""))+1,999),"")=SUBSTITUTE(SUBSTITUTE($B5," ",""),CHAR(160),"")),--ISNUMBER(SEARCH("|B->>F|","|"&IFERROR(LEFT(SUBSTITUTE(SUBSTITUTE(Operations!$D$4:$D$67," ",""),CHAR(160),""),FIND(":",SUBSTITUTE(SUBSTITUTE(Operations!$D$4:$D$67," ",""),CHAR(160),""))-1),"")&"|")))>0,"trovato","non trovato")} -> trovato
B6: instance/{cui_uuid}/document/{resource_id} | C6: {=IF(SUMPRODUCT(--(IFERROR(MID(SUBSTITUTE(SUBSTITUTE(Operations!$D$4:$D$67," ",""),CHAR(160),""),FIND(":",SUBSTITUTE(SUBSTITUTE(Operations!$D$4:$D$67," ",""),CHAR(160),""))+1,999),"")=SUBSTITUTE(SUBSTITUTE($B6," ",""),CHAR(160),"")),--ISNUMBER(SEARCH("|B->>F|","|"&IFERROR(LEFT(SUBSTITUTE(SUBSTITUTE(Operations!$D$4:$D$67," ",""),CHAR(160),""),FIND(":",SUBSTITUTE(SUBSTITUTE(Operations!$D$4:$D$67," ",""),CHAR(160),""))-1),"")&"|")))>0,"trovato","non trovato")} -> trovato
B7: notify | C7: {=IF(SUMPRODUCT(--(IFERROR(MID(SUBSTITUTE(SUBSTITUTE(Operations!$D$4:$D$67," ",""),CHAR(160),""),FIND(":",SUBSTITUTE(SUBSTITUTE(Operations!$D$4:$D$67," ",""),CHAR(160),""))+1,999),"")=SUBSTITUTE(SUBSTITUTE($B7," ",""),CHAR(160),"")),--ISNUMBER(SEARCH("|B->>F|","|"&IFERROR(LEFT(SUBSTITUTE(SUBSTITUTE(Operations!$D$4:$D$67," ",""),CHAR(160),""),FIND(":",SUBSTITUTE(SUBSTITUTE(Operations!$D$4:$D$67," ",""),CHAR(160),""))-1),"")&"|")))>0,"trovato","non trovato")} -> trovato
B8: cdss_resolution_forward | C8: {=IF(SUMPRODUCT(--(IFERROR(MID(SUBSTITUTE(SUBSTITUTE(Operations!$D$4:$D$67," ",""),CHAR(160),""),FIND(":",SUBSTITUTE(SUBSTITUTE(Operations!$D$4:$D$67," ",""),CHAR(160),""))+1,999),"")=SUBSTITUTE(SUBSTITUTE($B8," ",""),CHAR(160),"")),--ISNUMBER(SEARCH("|B->>F|","|"&IFERROR(LEFT(SUBSTITUTE(SUBSTITUTE(Operations!$D$4:$D$67," ",""),CHAR(160),""),FIND(":",SUBSTITUTE(SUBSTITUTE(Operations!$D$4:$D$67," ",""),CHAR(160),""))-1),"")&"|")))>0,"trovato","non trovato")} -> trovato

Sheet et_to_bo
B1: Operation | C1: Check
B2: retry | C2: {=IF(SUMPRODUCT(--(IFERROR(MID(SUBSTITUTE(SUBSTITUTE(Operations!$D$4:$D$67," ",""),CHAR(160),""),FIND(":",SUBSTITUTE(SUBSTITUTE(Operations!$D$4:$D$67," ",""),CHAR(160),""))+1,999),"")=SUBSTITUTE(SUBSTITUTE($B2," ",""),CHAR(160),"")),--ISNUMBER(SEARCH("|B->>E|","|"&IFERROR(LEFT(SUBSTITUTE(SUBSTITUTE(Operations!$D$4:$D$67," ",""),CHAR(160),""),FIND(":",SUBSTITUTE(SUBSTITUTE(Operations!$D$4:$D$67," ",""),CHAR(160),""))-1),"")&"|")))>0,"trovato","non trovato")} -> trovato
B3: send_instance | C3: {=IF(SUMPRODUCT(--(IFERROR(MID(SUBSTITUTE(SUBSTITUTE(Operations!$D$4:$D$67," ",""),CHAR(160),""),FIND(":",SUBSTITUTE(SUBSTITUTE(Operations!$D$4:$D$67," ",""),CHAR(160),""))+1,999),"")=SUBSTITUTE(SUBSTITUTE($B3," ",""),CHAR(160),"")),--ISNUMBER(SEARCH("|B->>E|","|"&IFERROR(LEFT(SUBSTITUTE(SUBSTITUTE(Operations!$D$4:$D$67," ",""),CHAR(160),""),FIND(":",SUBSTITUTE(SUBSTITUTE(Operations!$D$4:$D$67," ",""),CHAR(160),""))-1),"")&"|")))>0,"trovato","non trovato")} -> trovato
B4: send_instance_updated_documents | C4: {=IF(SUMPRODUCT(--(IFERROR(MID(SUBSTITUTE(SUBSTITUTE(Operations!$D$4:$D$67," ",""),CHAR(160),""),FIND(":",SUBSTITUTE(SUBSTITUTE(Operations!$D$4:$D$67," ",""),CHAR(160),""))+1,999),"")=SUBSTITUTE(SUBSTITUTE($B4," ",""),CHAR(160),"")),--ISNUMBER(SEARCH("|B->>E|","|"&IFERROR(LEFT(SUBSTITUTE(SUBSTITUTE(Operations!$D$4:$D$67," ",""),CHAR(160),""),FIND(":",SUBSTITUTE(SUBSTITUTE(Operations!$D$4:$D$67," ",""),CHAR(160),""))-1),"")&"|")))>0,"trovato","non trovato")} -> trovato
B5: instance/{cui_uuid}/document/{resource_id} | C5: {=IF(SUMPRODUCT(--(IFERROR(MID(SUBSTITUTE(SUBSTITUTE(Operations!$D$4:$D$67," ",""),CHAR(160),""),FIND(":",SUBSTITUTE(SUBSTITUTE(Operations!$D$4:$D$67," ",""),CHAR(160),""))+1,999),"")=SUBSTITUTE(SUBSTITUTE($B5," ",""),CHAR(160),"")),--ISNUMBER(SEARCH("|B->>E|","|"&IFERROR(LEFT(SUBSTITUTE(SUBSTITUTE(Operations!$D$4:$D$67," ",""),CHAR(160),""),FIND(":",SUBSTITUTE(SUBSTITUTE(Operations!$D$4:$D$67," ",""),CHAR(160),""))-1),"")&"|")))>0,"trovato","non trovato")} -> trovato
B6: notify | C6: {=IF(SUMPRODUCT(--(IFERROR(MID(SUBSTITUTE(SUBSTITUTE(Operations!$D$4:$D$67," ",""),CHAR(160),""),FIND(":",SUBSTITUTE(SUBSTITUTE(Operations!$D$4:$D$67," ",""),CHAR(160),""))+1,999),"")=SUBSTITUTE(SUBSTITUTE($B6," ",""),CHAR(160),"")),--ISNUMBER(SEARCH("|B->>E|","|"&IFERROR(LEFT(SUBSTITUTE(SUBSTITUTE(Operations!$D$4:$D$67," ",""),CHAR(160),""),FIND(":",SUBSTITUTE(SUBSTITUTE(Operations!$D$4:$D$67," ",""),CHAR(160),""))-1),"")&"|")))>0,"trovato","non trovato")} -> trovato
B7: cdss_resolution_forward | C7: {=IF(SUMPRODUCT(--(IFERROR(MID(SUBSTITUTE(SUBSTITUTE(Operations!$D$4:$D$67," ",""),CHAR(160),""),FIND(":",SUBSTITUTE(SUBSTITUTE(Operations!$D$4:$D$67," ",""),CHAR(160),""))+1,999),"")=SUBSTITUTE(SUBSTITUTE($B7," ",""),CHAR(160),"")),--ISNUMBER(SEARCH("|B->>E|","|"&IFERROR(LEFT(SUBSTITUTE(SUBSTITUTE(Operations!$D$4:$D$67," ",""),CHAR(160),""),FIND(":",SUBSTITUTE(SUBSTITUTE(Operations!$D$4:$D$67," ",""),CHAR(160),""))-1),"")&"|")))>0,"trovato","non trovato")} -> trovato

Sheet ri_to_bo
B1: Operation | C1: Check
B2: send_instance | C2: {=IF(SUMPRODUCT(--(IFERROR(MID(SUBSTITUTE(SUBSTITUTE(Operations!$D$4:$D$67," ",""),CHAR(160),""),FIND(":",SUBSTITUTE(SUBSTITUTE(Operations!$D$4:$D$67," ",""),CHAR(160),""))+1,999),"")=SUBSTITUTE(SUBSTITUTE($B2," ",""),CHAR(160),"")),--ISNUMBER(SEARCH("|B->>RI|","|"&IFERROR(LEFT(SUBSTITUTE(SUBSTITUTE(Operations!$D$4:$D$67," ",""),CHAR(160),""),FIND(":",SUBSTITUTE(SUBSTITUTE(Operations!$D$4:$D$67," ",""),CHAR(160),""))-1),"")&"|")))>0,"trovato","non trovato")} -> trovato
B3: notify | C3: {=IF(SUMPRODUCT(--(IFERROR(MID(SUBSTITUTE(SUBSTITUTE(Operations!$D$4:$D$67," ",""),CHAR(160),""),FIND(":",SUBSTITUTE(SUBSTITUTE(Operations!$D$4:$D$67," ",""),CHAR(160),""))+1,999),"")=SUBSTITUTE(SUBSTITUTE($B3," ",""),CHAR(160),"")),--ISNUMBER(SEARCH("|B->>RI|","|"&IFERROR(LEFT(SUBSTITUTE(SUBSTITUTE(Operations!$D$4:$D$67," ",""),CHAR(160),""),FIND(":",SUBSTITUTE(SUBSTITUTE(Operations!$D$4:$D$67," ",""),CHAR(160),""))-1),"")&"|")))>0,"trovato","non trovato")} -> trovato
B4: retry | C4: {=IF(SUMPRODUCT(--(IFERROR(MID(SUBSTITUTE(SUBSTITUTE(Operations!$D$4:$D$67," ",""),CHAR(160),""),FIND(":",SUBSTITUTE(SUBSTITUTE(Operations!$D$4:$D$67," ",""),CHAR(160),""))+1,999),"")=SUBSTITUTE(SUBSTITUTE($B4," ",""),CHAR(160),"")),--ISNUMBER(SEARCH("|B->>RI|","|"&IFERROR(LEFT(SUBSTITUTE(SUBSTITUTE(Operations!$D$4:$D$67," ",""),CHAR(160),""),FIND(":",SUBSTITUTE(SUBSTITUTE(Operations!$D$4:$D$67," ",""),CHAR(160),""))-1),"")&"|")))>0,"trovato","non trovato")} -> trovato
B5: instance/{cui_uuid}/document/{resource_id} | C5: {=IF(SUMPRODUCT(--(IFERROR(MID(SUBSTITUTE(SUBSTITUTE(Operations!$D$4:$D$67," ",""),CHAR(160),""),FIND(":",SUBSTITUTE(SUBSTITUTE(Operations!$D$4:$D$67," ",""),CHAR(160),""))+1,999),"")=SUBSTITUTE(SUBSTITUTE($B5," ",""),CHAR(160),"")),--ISNUMBER(SEARCH("|B->>RI|","|"&IFERROR(LEFT(SUBSTITUTE(SUBSTITUTE(Operations!$D$4:$D$67," ",""),CHAR(160),""),FIND(":",SUBSTITUTE(SUBSTITUTE(Operations!$D$4:$D$67," ",""),CHAR(160),""))-1),"")&"|")))>0,"trovato","non trovato")} -> trovato

Sheet bozes_to_boadsp
B1: Operation | C1: Check
B2: retry | C2: {=IF(SUMPRODUCT(--(IFERROR(MID(SUBSTITUTE(SUBSTITUTE(Operations!$D$4:$D$67," ",""),CHAR(160),""),FIND(":",SUBSTITUTE(SUBSTITUTE(Operations!$D$4:$D$67," ",""),CHAR(160),""))+1,999),"")=SUBSTITUTE(SUBSTITUTE($B2," ",""),CHAR(160),"")),--ISNUMBER(SEARCH("|BOZES->>BOADSP|","|"&IFERROR(LEFT(SUBSTITUTE(SUBSTITUTE(Operations!$D$4:$D$67," ",""),CHAR(160),""),FIND(":",SUBSTITUTE(SUBSTITUTE(Operations!$D$4:$D$67," ",""),CHAR(160),""))-1),"")&"|")))>0,"trovato","non trovato")} -> trovato
B3: transfer_instance | C3: {=IF(SUMPRODUCT(--(IFERROR(MID(SUBSTITUTE(SUBSTITUTE(Operations!$D$4:$D$67," ",""),CHAR(160),""),FIND(":",SUBSTITUTE(SUBSTITUTE(Operations!$D$4:$D$67," ",""),CHAR(160),""))+1,999),"")=SUBSTITUTE(SUBSTITUTE($B3," ",""),CHAR(160),"")),--ISNUMBER(SEARCH("|BOZES->>BOADSP|","|"&IFERROR(LEFT(SUBSTITUTE(SUBSTITUTE(Operations!$D$4:$D$67," ",""),CHAR(160),""),FIND(":",SUBSTITUTE(SUBSTITUTE(Operations!$D$4:$D$67," ",""),CHAR(160),""))-1),"")&"|")))>0,"trovato","non trovato")} -> trovato
B4: instance/{cui_uuid}/document/{resource_id} | C4: {=IF(SUMPRODUCT(--(IFERROR(MID(SUBSTITUTE(SUBSTITUTE(Operations!$D$4:$D$67," ",""),CHAR(160),""),FIND(":",SUBSTITUTE(SUBSTITUTE(Operations!$D$4:$D$67," ",""),CHAR(160),""))+1,999),"")=SUBSTITUTE(SUBSTITUTE($B4," ",""),CHAR(160),"")),--ISNUMBER(SEARCH("|BOZES->>BOADSP|","|"&IFERROR(LEFT(SUBSTITUTE(SUBSTITUTE(Operations!$D$4:$D$67," ",""),CHAR(160),""),FIND(":",SUBSTITUTE(SUBSTITUTE(Operations!$D$4:$D$67," ",""),CHAR(160),""))-1),"")&"|")))>0,"trovato","non trovato")} -> trovato

Sheet boadsp_to_bozes
B1: Operation | C1: Check
B2: retry | C2: {=IF(SUMPRODUCT(--(IFERROR(MID(SUBSTITUTE(SUBSTITUTE(Operations!$D$4:$D$67," ",""),CHAR(160),""),FIND(":",SUBSTITUTE(SUBSTITUTE(Operations!$D$4:$D$67," ",""),CHAR(160),""))+1,999),"")=SUBSTITUTE(SUBSTITUTE($B2," ",""),CHAR(160),"")),--ISNUMBER(SEARCH("|BOZES->>BOADSP|","|"&IFERROR(LEFT(SUBSTITUTE(SUBSTITUTE(Operations!$D$4:$D$67," ",""),CHAR(160),""),FIND(":",SUBSTITUTE(SUBSTITUTE(Operations!$D$4:$D$67," ",""),CHAR(160),""))-1),"")&"|")))>0,"trovato","non trovato")} -> trovato
B3: notify | C3: {=IF(SUMPRODUCT(--(IFERROR(MID(SUBSTITUTE(SUBSTITUTE(Operations!$D$4:$D$67," ",""),CHAR(160),""),FIND(":",SUBSTITUTE(SUBSTITUTE(Operations!$D$4:$D$67," ",""),CHAR(160),""))+1,999),"")=SUBSTITUTE(SUBSTITUTE($B3," ",""),CHAR(160),"")),--ISNUMBER(SEARCH("|BOADSP->>BOZES|","|"&IFERROR(LEFT(SUBSTITUTE(SUBSTITUTE(Operations!$D$4:$D$67," ",""),CHAR(160),""),FIND(":",SUBSTITUTE(SUBSTITUTE(Operations!$D$4:$D$67," ",""),CHAR(160),""))-1),"")&"|")))>0,"trovato","non trovato")} -> trovato

Sheet catalogo-ssu_to_bo
B1: Operation | C1: Check
B2: instance_descriptor | C2: {=IF(SUMPRODUCT(--(IFERROR(MID(SUBSTITUTE(SUBSTITUTE(Operations!$D$4:$D$67," ",""),CHAR(160),""),FIND(":",SUBSTITUTE(SUBSTITUTE(Operations!$D$4:$D$67," ",""),CHAR(160),""))+1,999),"")=SUBSTITUTE(SUBSTITUTE($B2," ",""),CHAR(160),"")),--ISNUMBER(SEARCH("|B->>C|","|"&IFERROR(LEFT(SUBSTITUTE(SUBSTITUTE(Operations!$D$4:$D$67," ",""),CHAR(160),""),FIND(":",SUBSTITUTE(SUBSTITUTE(Operations!$D$4:$D$67," ",""),CHAR(160),""))-1),"")&"|")))>0,"trovato","non trovato")} -> trovato
B3: update_times | C3: {=IF(SUMPRODUCT(--(IFERROR(MID(SUBSTITUTE(SUBSTITUTE(Operations!$D$4:$D$67," ",""),CHAR(160),""),FIND(":",SUBSTITUTE(SUBSTITUTE(Operations!$D$4:$D$67," ",""),CHAR(160),""))+1,999),"")=SUBSTITUTE(SUBSTITUTE($B3," ",""),CHAR(160),"")),--ISNUMBER(SEARCH("|B->>C|","|"&IFERROR(LEFT(SUBSTITUTE(SUBSTITUTE(Operations!$D$4:$D$67," ",""),CHAR(160),""),FIND(":",SUBSTITUTE(SUBSTITUTE(Operations!$D$4:$D$67," ",""),CHAR(160),""))-1),"")&"|")))>0,"trovato","non trovato")} -> trovato
B4: update_attachments_and_times | C4: {=IF(SUMPRODUCT(--(IFERROR(MID(SUBSTITUTE(SUBSTITUTE(Operations!$D$4:$D$67," ",""),CHAR(160),""),FIND(":",SUBSTITUTE(SUBSTITUTE(Operations!$D$4:$D$67," ",""),CHAR(160),""))+1,999),"")=SUBSTITUTE(SUBSTITUTE($B4," ",""),CHAR(160),"")),--ISNUMBER(SEARCH("|B->>C|","|"&IFERROR(LEFT(SUBSTITUTE(SUBSTITUTE(Operations!$D$4:$D$67," ",""),CHAR(160),""),FIND(":",SUBSTITUTE(SUBSTITUTE(Operations!$D$4:$D$67," ",""),CHAR(160),""))-1),"")&"|")))>0,"trovato","non trovato")} -> trovato
B5: update_instances_and_times | C5: {=IF(SUMPRODUCT(--(IFERROR(MID(SUBSTITUTE(SUBSTITUTE(Operations!$D$4:$D$67," ",""),CHAR(160),""),FIND(":",SUBSTITUTE(SUBSTITUTE(Operations!$D$4:$D$67," ",""),CHAR(160),""))+1,999),"")=SUBSTITUTE(SUBSTITUTE($B5," ",""),CHAR(160),"")),--ISNUMBER(SEARCH("|B->>C|","|"&IFERROR(LEFT(SUBSTITUTE(SUBSTITUTE(Operations!$D$4:$D$67," ",""),CHAR(160),""),FIND(":",SUBSTITUTE(SUBSTITUTE(Operations!$D$4:$D$67," ",""),CHAR(160),""))-1),"")&"|")))>0,"trovato","non trovato")} -> non trovato | D5: (non in uso nei flussi)
B6: add_interested_administration | C6: {=IF(SUMPRODUCT(--(IFERROR(MID(SUBSTITUTE(SUBSTITUTE(Operations!$D$4:$D$67," ",""),CHAR(160),""),FIND(":",SUBSTITUTE(SUBSTITUTE(Operations!$D$4:$D$67," ",""),CHAR(160),""))+1,999),"")=SUBSTITUTE(SUBSTITUTE($B6," ",""),CHAR(160),"")),--ISNUMBER(SEARCH("|B->>C|","|"&IFERROR(LEFT(SUBSTITUTE(SUBSTITUTE(Operations!$D$4:$D$67," ",""),CHAR(160),""),FIND(":",SUBSTITUTE(SUBSTITUTE(Operations!$D$4:$D$67," ",""),CHAR(160),""))-1),"")&"|")))>0,"trovato","non trovato")} -> trovato
B7: audit | C7: {=IF(SUMPRODUCT(--(IFERROR(MID(SUBSTITUTE(SUBSTITUTE(Operations!$D$4:$D$67," ",""),CHAR(160),""),FIND(":",SUBSTITUTE(SUBSTITUTE(Operations!$D$4:$D$67," ",""),CHAR(160),""))+1,999),"")=SUBSTITUTE(SUBSTITUTE($B7," ",""),CHAR(160),"")),--ISNUMBER(SEARCH("|B->>C|","|"&IFERROR(LEFT(SUBSTITUTE(SUBSTITUTE(Operations!$D$4:$D$67," ",""),CHAR(160),""),FIND(":",SUBSTITUTE(SUBSTITUTE(Operations!$D$4:$D$67," ",""),CHAR(160),""))-1),"")&"|")))>0,"trovato","non trovato")} -> trovato
B8: add_permit_document | C8: {=IF(SUMPRODUCT(--(IFERROR(MID(SUBSTITUTE(SUBSTITUTE(Operations!$D$4:$D$67," ",""),CHAR(160),""),FIND(":",SUBSTITUTE(SUBSTITUTE(Operations!$D$4:$D$67," ",""),CHAR(160),""))+1,999),"")=SUBSTITUTE(SUBSTITUTE($B8," ",""),CHAR(160),"")),--ISNUMBER(SEARCH("|B->>C|","|"&IFERROR(LEFT(SUBSTITUTE(SUBSTITUTE(Operations!$D$4:$D$67," ",""),CHAR(160),""),FIND(":",SUBSTITUTE(SUBSTITUTE(Operations!$D$4:$D$67," ",""),CHAR(160),""))-1),"")&"|")))>0,"trovato","non trovato")} -> trovato
B9: revoke_permit_document | C9: {=IF(SUMPRODUCT(--(IFERROR(MID(SUBSTITUTE(SUBSTITUTE(Operations!$D$4:$D$67," ",""),CHAR(160),""),FIND(":",SUBSTITUTE(SUBSTITUTE(Operations!$D$4:$D$67," ",""),CHAR(160),""))+1,999),"")=SUBSTITUTE(SUBSTITUTE($B9," ",""),CHAR(160),"")),--ISNUMBER(SEARCH("|B->>C|","|"&IFERROR(LEFT(SUBSTITUTE(SUBSTITUTE(Operations!$D$4:$D$67," ",""),CHAR(160),""),FIND(":",SUBSTITUTE(SUBSTITUTE(Operations!$D$4:$D$67," ",""),CHAR(160),""))-1),"")&"|")))>0,"trovato","non trovato")} -> trovato

Sheet bo_to_et
B1: Operation | C1: Check
B2: retry | C2: {=IF(SUMPRODUCT(--(IFERROR(MID(SUBSTITUTE(SUBSTITUTE(Operations!$E$4:$E$67," ",""),CHAR(160),""),FIND(":",SUBSTITUTE(SUBSTITUTE(Operations!$E$4:$E$67," ",""),CHAR(160),""))+1,999),"")=SUBSTITUTE(SUBSTITUTE($B2," ",""),CHAR(160),"")),--ISNUMBER(SEARCH("|E->>B|","|"&IFERROR(LEFT(SUBSTITUTE(SUBSTITUTE(Operations!$E$4:$E$67," ",""),CHAR(160),""),FIND(":",SUBSTITUTE(SUBSTITUTE(Operations!$E$4:$E$67," ",""),CHAR(160),""))-1),"")&"|")))>0,"trovato","non trovato")} -> trovato
B3: send_impediments | C3: {=IF(SUMPRODUCT(--(IFERROR(MID(SUBSTITUTE(SUBSTITUTE(Operations!$E$4:$E$67," ",""),CHAR(160),""),FIND(":",SUBSTITUTE(SUBSTITUTE(Operations!$E$4:$E$67," ",""),CHAR(160),""))+1,999),"")=SUBSTITUTE(SUBSTITUTE($B3," ",""),CHAR(160),"")),--ISNUMBER(SEARCH("|E->>B|","|"&IFERROR(LEFT(SUBSTITUTE(SUBSTITUTE(Operations!$E$4:$E$67," ",""),CHAR(160),""),FIND(":",SUBSTITUTE(SUBSTITUTE(Operations!$E$4:$E$67," ",""),CHAR(160),""))-1),"")&"|")))>0,"trovato","non trovato")} -> trovato
B4: send_conclusions | C4: {=IF(SUMPRODUCT(--(IFERROR(MID(SUBSTITUTE(SUBSTITUTE(Operations!$E$4:$E$67," ",""),CHAR(160),""),FIND(":",SUBSTITUTE(SUBSTITUTE(Operations!$E$4:$E$67," ",""),CHAR(160),""))+1,999),"")=SUBSTITUTE(SUBSTITUTE($B4," ",""),CHAR(160),"")),--ISNUMBER(SEARCH("|E->>B|","|"&IFERROR(LEFT(SUBSTITUTE(SUBSTITUTE(Operations!$E$4:$E$67," ",""),CHAR(160),""),FIND(":",SUBSTITUTE(SUBSTITUTE(Operations!$E$4:$E$67," ",""),CHAR(160),""))-1),"")&"|")))>0,"trovato","non trovato")} -> trovato
B5: send_conditional_provision | C5: {=IF(SUMPRODUCT(--(IFERROR(MID(SUBSTITUTE(SUBSTITUTE(Operations!$E$4:$E$67," ",""),CHAR(160),""),FIND(":",SUBSTITUTE(SUBSTITUTE(Operations!$E$4:$E$67," ",""),CHAR(160),""))+1,999),"")=SUBSTITUTE(SUBSTITUTE($B5," ",""),CHAR(160),"")),--ISNUMBER(SEARCH("|E->>B|","|"&IFERROR(LEFT(SUBSTITUTE(SUBSTITUTE(Operations!$E$4:$E$67," ",""),CHAR(160),""),FIND(":",SUBSTITUTE(SUBSTITUTE(Operations!$E$4:$E$67," ",""),CHAR(160),""))-1),"")&"|")))>0,"trovato","non trovato")} -> trovato
B6: request_cdss | C6: {=IF(SUMPRODUCT(--(IFERROR(MID(SUBSTITUTE(SUBSTITUTE(Operations!$E$4:$E$67," ",""),CHAR(160),""),FIND(":",SUBSTITUTE(SUBSTITUTE(Operations!$E$4:$E$67," ",""),CHAR(160),""))+1,999),"")=SUBSTITUTE(SUBSTITUTE($B6," ",""),CHAR(160),"")),--ISNUMBER(SEARCH("|E->>B|","|"&IFERROR(LEFT(SUBSTITUTE(SUBSTITUTE(Operations!$E$4:$E$67," ",""),CHAR(160),""),FIND(":",SUBSTITUTE(SUBSTITUTE(Operations!$E$4:$E$67," ",""),CHAR(160),""))-1),"")&"|")))>0,"trovato","non trovato")} -> trovato
B7: request_integration | C7: {=IF(SUMPRODUCT(--(IFERROR(MID(SUBSTITUTE(SUBSTITUTE(Operations!$E$4:$E$67," ",""),CHAR(160),""),FIND(":",SUBSTITUTE(SUBSTITUTE(Operations!$E$4:$E$67," ",""),CHAR(160),""))+1,999),"")=SUBSTITUTE(SUBSTITUTE($B7," ",""),CHAR(160),"")),--ISNUMBER(SEARCH("|E->>B|","|"&IFERROR(LEFT(SUBSTITUTE(SUBSTITUTE(Operations!$E$4:$E$67," ",""),CHAR(160),""),FIND(":",SUBSTITUTE(SUBSTITUTE(Operations!$E$4:$E$67," ",""),CHAR(160),""))-1),"")&"|")))>0,"trovato","non trovato")} -> trovato
B8: request_conformation | C8: {=IF(SUMPRODUCT(--(IFERROR(MID(SUBSTITUTE(SUBSTITUTE(Operations!$E$4:$E$67," ",""),CHAR(160),""),FIND(":",SUBSTITUTE(SUBSTITUTE(Operations!$E$4:$E$67," ",""),CHAR(160),""))+1,999),"")=SUBSTITUTE(SUBSTITUTE($B8," ",""),CHAR(160),"")),--ISNUMBER(SEARCH("|E->>B|","|"&IFERROR(LEFT(SUBSTITUTE(SUBSTITUTE(Operations!$E$4:$E$67," ",""),CHAR(160),""),FIND(":",SUBSTITUTE(SUBSTITUTE(Operations!$E$4:$E$67," ",""),CHAR(160),""))-1),"")&"|")))>0,"trovato","non trovato")} -> trovato
B9: instance/{cui_uuid}/document/{resource_id} | C9: {=IF(SUMPRODUCT(--(IFERROR(MID(SUBSTITUTE(SUBSTITUTE(Operations!$E$4:$E$67," ",""),CHAR(160),""),FIND(":",SUBSTITUTE(SUBSTITUTE(Operations!$E$4:$E$67," ",""),CHAR(160),""))+1,999),"")=SUBSTITUTE(SUBSTITUTE($B9," ",""),CHAR(160),"")),--ISNUMBER(SEARCH("|E->>B|","|"&IFERROR(LEFT(SUBSTITUTE(SUBSTITUTE(Operations!$E$4:$E$67," ",""),CHAR(160),""),FIND(":",SUBSTITUTE(SUBSTITUTE(Operations!$E$4:$E$67," ",""),CHAR(160),""))-1),"")&"|")))>0,"trovato","non trovato")} -> trovato
B10: notify | C10: {=IF(SUMPRODUCT(--(IFERROR(MID(SUBSTITUTE(SUBSTITUTE(Operations!$E$4:$E$67," ",""),CHAR(160),""),FIND(":",SUBSTITUTE(SUBSTITUTE(Operations!$E$4:$E$67," ",""),CHAR(160),""))+1,999),"")=SUBSTITUTE(SUBSTITUTE($B10," ",""),CHAR(160),"")),--ISNUMBER(SEARCH("|E->>B|","|"&IFERROR(LEFT(SUBSTITUTE(SUBSTITUTE(Operations!$E$4:$E$67," ",""),CHAR(160),""),FIND(":",SUBSTITUTE(SUBSTITUTE(Operations!$E$4:$E$67," ",""),CHAR(160),""))-1),"")&"|")))>0,"trovato","non trovato")} -> trovato
B11: send_extension_conditional_provision | C11: {=IF(SUMPRODUCT(--(IFERROR(MID(SUBSTITUTE(SUBSTITUTE(Operations!$E$4:$E$67," ",""),CHAR(160),""),FIND(":",SUBSTITUTE(SUBSTITUTE(Operations!$E$4:$E$67," ",""),CHAR(160),""))+1,999),"")=SUBSTITUTE(SUBSTITUTE($B11," ",""),CHAR(160),"")),--ISNUMBER(SEARCH("|E->>B|","|"&IFERROR(LEFT(SUBSTITUTE(SUBSTITUTE(Operations!$E$4:$E$67," ",""),CHAR(160),""),FIND(":",SUBSTITUTE(SUBSTITUTE(Operations!$E$4:$E$67," ",""),CHAR(160),""))-1),"")&"|")))>0,"trovato","non trovato")} -> trovato
B12: send_generic_communication | C12: {=IF(SUMPRODUCT(--(IFERROR(MID(SUBSTITUTE(SUBSTITUTE(Operations!$E$4:$E$67," ",""),CHAR(160),""),FIND(":",SUBSTITUTE(SUBSTITUTE(Operations!$E$4:$E$67," ",""),CHAR(160),""))+1,999),"")=SUBSTITUTE(SUBSTITUTE($B12," ",""),CHAR(160),"")),--ISNUMBER(SEARCH("|E->>B|","|"&IFERROR(LEFT(SUBSTITUTE(SUBSTITUTE(Operations!$E$4:$E$67," ",""),CHAR(160),""),FIND(":",SUBSTITUTE(SUBSTITUTE(Operations!$E$4:$E$67," ",""),CHAR(160),""))-1),"")&"|")))>0,"trovato","non trovato")} -> trovato

Sheet et_to_et
B1: Operation | C1: Check
B2: send_instance | C2: {=IF(SUMPRODUCT(--(IFERROR(MID(SUBSTITUTE(SUBSTITUTE(Operations!$E$4:$E$67," ",""),CHAR(160),""),FIND(":",SUBSTITUTE(SUBSTITUTE(Operations!$E$4:$E$67," ",""),CHAR(160),""))+1,999),"")=SUBSTITUTE(SUBSTITUTE($B2," ",""),CHAR(160),"")),--ISNUMBER(SEARCH("|E->>E|","|"&IFERROR(LEFT(SUBSTITUTE(SUBSTITUTE(Operations!$E$4:$E$67," ",""),CHAR(160),""),FIND(":",SUBSTITUTE(SUBSTITUTE(Operations!$E$4:$E$67," ",""),CHAR(160),""))-1),"")&"|")))>0,"trovato","non trovato")} -> trovato
B3: instance/{cui_uuid}/document/{resource_id} | C3: {=IF(SUMPRODUCT(--(IFERROR(MID(SUBSTITUTE(SUBSTITUTE(Operations!$E$4:$E$67," ",""),CHAR(160),""),FIND(":",SUBSTITUTE(SUBSTITUTE(Operations!$E$4:$E$67," ",""),CHAR(160),""))+1,999),"")=SUBSTITUTE(SUBSTITUTE($B3," ",""),CHAR(160),"")),--ISNUMBER(SEARCH("|E->>E|","|"&IFERROR(LEFT(SUBSTITUTE(SUBSTITUTE(Operations!$E$4:$E$67," ",""),CHAR(160),""),FIND(":",SUBSTITUTE(SUBSTITUTE(Operations!$E$4:$E$67," ",""),CHAR(160),""))-1),"")&"|")))>0,"trovato","non trovato")} -> non trovato | D3: (non presente nel flusso)
B4: request_integration | C4: {=IF(SUMPRODUCT(--(IFERROR(MID(SUBSTITUTE(SUBSTITUTE(Operations!$E$4:$E$67," ",""),CHAR(160),""),FIND(":",SUBSTITUTE(SUBSTITUTE(Operations!$E$4:$E$67," ",""),CHAR(160),""))+1,999),"")=SUBSTITUTE(SUBSTITUTE($B4," ",""),CHAR(160),"")),--ISNUMBER(SEARCH("|E->>E|","|"&IFERROR(LEFT(SUBSTITUTE(SUBSTITUTE(Operations!$E$4:$E$67," ",""),CHAR(160),""),FIND(":",SUBSTITUTE(SUBSTITUTE(Operations!$E$4:$E$67," ",""),CHAR(160),""))-1),"")&"|")))>0,"trovato","non trovato")} -> trovato
B5: request_conformation | C5: {=IF(SUMPRODUCT(--(IFERROR(MID(SUBSTITUTE(SUBSTITUTE(Operations!$E$4:$E$67," ",""),CHAR(160),""),FIND(":",SUBSTITUTE(SUBSTITUTE(Operations!$E$4:$E$67," ",""),CHAR(160),""))+1,999),"")=SUBSTITUTE(SUBSTITUTE($B5," ",""),CHAR(160),"")),--ISNUMBER(SEARCH("|E->>E|","|"&IFERROR(LEFT(SUBSTITUTE(SUBSTITUTE(Operations!$E$4:$E$67," ",""),CHAR(160),""),FIND(":",SUBSTITUTE(SUBSTITUTE(Operations!$E$4:$E$67," ",""),CHAR(160),""))-1),"")&"|")))>0,"trovato","non trovato")} -> trovato
B6: request_cdss | C6: {=IF(SUMPRODUCT(--(IFERROR(MID(SUBSTITUTE(SUBSTITUTE(Operations!$E$4:$E$67," ",""),CHAR(160),""),FIND(":",SUBSTITUTE(SUBSTITUTE(Operations!$E$4:$E$67," ",""),CHAR(160),""))+1,999),"")=SUBSTITUTE(SUBSTITUTE($B6," ",""),CHAR(160),"")),--ISNUMBER(SEARCH("|E->>E|","|"&IFERROR(LEFT(SUBSTITUTE(SUBSTITUTE(Operations!$E$4:$E$67," ",""),CHAR(160),""),FIND(":",SUBSTITUTE(SUBSTITUTE(Operations!$E$4:$E$67," ",""),CHAR(160),""))-1),"")&"|")))>0,"trovato","non trovato")} -> trovato
B7: send_conclusions | C7: {=IF(SUMPRODUCT(--(IFERROR(MID(SUBSTITUTE(SUBSTITUTE(Operations!$E$4:$E$67," ",""),CHAR(160),""),FIND(":",SUBSTITUTE(SUBSTITUTE(Operations!$E$4:$E$67," ",""),CHAR(160),""))+1,999),"")=SUBSTITUTE(SUBSTITUTE($B7," ",""),CHAR(160),"")),--ISNUMBER(SEARCH("|E->>E|","|"&IFERROR(LEFT(SUBSTITUTE(SUBSTITUTE(Operations!$E$4:$E$67," ",""),CHAR(160),""),FIND(":",SUBSTITUTE(SUBSTITUTE(Operations!$E$4:$E$67," ",""),CHAR(160),""))-1),"")&"|")))>0,"trovato","non trovato")} -> trovato
B8: notify | C8: {=IF(SUMPRODUCT(--(IFERROR(MID(SUBSTITUTE(SUBSTITUTE(Operations!$E$4:$E$67," ",""),CHAR(160),""),FIND(":",SUBSTITUTE(SUBSTITUTE(Operations!$E$4:$E$67," ",""),CHAR(160),""))+1,999),"")=SUBSTITUTE(SUBSTITUTE($B8," ",""),CHAR(160),"")),--ISNUMBER(SEARCH("|E->>E|","|"&IFERROR(LEFT(SUBSTITUTE(SUBSTITUTE(Operations!$E$4:$E$67," ",""),CHAR(160),""),FIND(":",SUBSTITUTE(SUBSTITUTE(Operations!$E$4:$E$67," ",""),CHAR(160),""))-1),"")&"|")))>0,"trovato","non trovato")} -> trovato
B9: retry | C9: {=IF(SUMPRODUCT(--(IFERROR(MID(SUBSTITUTE(SUBSTITUTE(Operations!$E$4:$E$67," ",""),CHAR(160),""),FIND(":",SUBSTITUTE(SUBSTITUTE(Operations!$E$4:$E$67," ",""),CHAR(160),""))+1,999),"")=SUBSTITUTE(SUBSTITUTE($B9," ",""),CHAR(160),"")),--ISNUMBER(SEARCH("|E->>E|","|"&IFERROR(LEFT(SUBSTITUTE(SUBSTITUTE(Operations!$E$4:$E$67," ",""),CHAR(160),""),FIND(":",SUBSTITUTE(SUBSTITUTE(Operations!$E$4:$E$67," ",""),CHAR(160),""))-1),"")&"|")))>0,"trovato","non trovato")} -> non trovato | D9: (non presente nel flusso)

Sheet catalogo-ssu_to_et
B1: Operation | C1: Check
B2: instance_descriptor | C2: {=IF(SUMPRODUCT(--(IFERROR(MID(SUBSTITUTE(SUBSTITUTE(Operations!$E$4:$E$67," ",""),CHAR(160),""),FIND(":",SUBSTITUTE(SUBSTITUTE(Operations!$E$4:$E$67," ",""),CHAR(160),""))+1,999),"")=SUBSTITUTE(SUBSTITUTE($B2," ",""),CHAR(160),"")),--ISNUMBER(SEARCH("|E->>C|","|"&IFERROR(LEFT(SUBSTITUTE(SUBSTITUTE(Operations!$E$4:$E$67," ",""),CHAR(160),""),FIND(":",SUBSTITUTE(SUBSTITUTE(Operations!$E$4:$E$67," ",""),CHAR(160),""))-1),"")&"|")))>0,"trovato","non trovato")} -> trovato
B3: audit | C3: {=IF(SUMPRODUCT(--(IFERROR(MID(SUBSTITUTE(SUBSTITUTE(Operations!$E$4:$E$67," ",""),CHAR(160),""),FIND(":",SUBSTITUTE(SUBSTITUTE(Operations!$E$4:$E$67," ",""),CHAR(160),""))+1,999),"")=SUBSTITUTE(SUBSTITUTE($B3," ",""),CHAR(160),"")),--ISNUMBER(SEARCH("|E->>C|","|"&IFERROR(LEFT(SUBSTITUTE(SUBSTITUTE(Operations!$E$4:$E$67," ",""),CHAR(160),""),FIND(":",SUBSTITUTE(SUBSTITUTE(Operations!$E$4:$E$67," ",""),CHAR(160),""))-1),"")&"|")))>0,"trovato","non trovato")} -> trovato
B4: administration_ghost | C4: {=IF(SUMPRODUCT(--(IFERROR(MID(SUBSTITUTE(SUBSTITUTE(Operations!$E$4:$E$67," ",""),CHAR(160),""),FIND(":",SUBSTITUTE(SUBSTITUTE(Operations!$E$4:$E$67," ",""),CHAR(160),""))+1,999),"")=SUBSTITUTE(SUBSTITUTE($B4," ",""),CHAR(160),"")),--ISNUMBER(SEARCH("|E->>C|","|"&IFERROR(LEFT(SUBSTITUTE(SUBSTITUTE(Operations!$E$4:$E$67," ",""),CHAR(160),""),FIND(":",SUBSTITUTE(SUBSTITUTE(Operations!$E$4:$E$67," ",""),CHAR(160),""))-1),"")&"|")))>0,"trovato","non trovato")} -> trovato

Sheet fo_to_cu
B1: Operation | C1: Check
B2: fo-portal-ref | C2: {=IF(SUMPRODUCT(--(IFERROR(MID(SUBSTITUTE(SUBSTITUTE(Operations!$F$4:$F$67," ",""),CHAR(160),""),FIND(":",SUBSTITUTE(SUBSTITUTE(Operations!$F$4:$F$67," ",""),CHAR(160),""))+1,999),"")=SUBSTITUTE(SUBSTITUTE($B2," ",""),CHAR(160),"")),--ISNUMBER(SEARCH("|CU->>F|","|"&IFERROR(LEFT(SUBSTITUTE(SUBSTITUTE(Operations!$F$4:$F$67," ",""),CHAR(160),""),FIND(":",SUBSTITUTE(SUBSTITUTE(Operations!$F$4:$F$67," ",""),CHAR(160),""))-1),"")&"|")))>0,"trovato","non trovato")} -> trovato
B3: retry | C3: {=IF(SUMPRODUCT(--(IFERROR(MID(SUBSTITUTE(SUBSTITUTE(Operations!$F$4:$F$67," ",""),CHAR(160),""),FIND(":",SUBSTITUTE(SUBSTITUTE(Operations!$F$4:$F$67," ",""),CHAR(160),""))+1,999),"")=SUBSTITUTE(SUBSTITUTE($B3," ",""),CHAR(160),"")),--ISNUMBER(SEARCH("|CU->>F|","|"&IFERROR(LEFT(SUBSTITUTE(SUBSTITUTE(Operations!$F$4:$F$67," ",""),CHAR(160),""),FIND(":",SUBSTITUTE(SUBSTITUTE(Operations!$F$4:$F$67," ",""),CHAR(160),""))-1),"")&"|")))>0,"trovato","non trovato")} -> trovato
B4: notify_receipt | C4: {=IF(SUMPRODUCT(--(IFERROR(MID(SUBSTITUTE(SUBSTITUTE(Operations!$F$4:$F$67," ",""),CHAR(160),""),FIND(":",SUBSTITUTE(SUBSTITUTE(Operations!$F$4:$F$67," ",""),CHAR(160),""))+1,999),"")=SUBSTITUTE(SUBSTITUTE($B4," ",""),CHAR(160),"")),--ISNUMBER(SEARCH("|CU->>F|","|"&IFERROR(LEFT(SUBSTITUTE(SUBSTITUTE(Operations!$F$4:$F$67," ",""),CHAR(160),""),FIND(":",SUBSTITUTE(SUBSTITUTE(Operations!$F$4:$F$67," ",""),CHAR(160),""))-1),"")&"|")))>0,"trovato","non trovato")} -> trovato
B5: instance/{cui_uuid}/document/{resource_id} | C5: {=IF(SUMPRODUCT(--(IFERROR(MID(SUBSTITUTE(SUBSTITUTE(Operations!$F$4:$F$67," ",""),CHAR(160),""),FIND(":",SUBSTITUTE(SUBSTITUTE(Operations!$F$4:$F$67," ",""),CHAR(160),""))+1,999),"")=SUBSTITUTE(SUBSTITUTE($B5," ",""),CHAR(160),"")),--ISNUMBER(SEARCH("|CU->>F|","|"&IFERROR(LEFT(SUBSTITUTE(SUBSTITUTE(Operations!$F$4:$F$67," ",""),CHAR(160),""),FIND(":",SUBSTITUTE(SUBSTITUTE(Operations!$F$4:$F$67," ",""),CHAR(160),""))-1),"")&"|")))>0,"trovato","non trovato")} -> trovato
B6: cancel_instance | C6: {=IF(SUMPRODUCT(--(IFERROR(MID(SUBSTITUTE(SUBSTITUTE(Operations!$F$4:$F$67," ",""),CHAR(160),""),FIND(":",SUBSTITUTE(SUBSTITUTE(Operations!$F$4:$F$67," ",""),CHAR(160),""))+1,999),"")=SUBSTITUTE(SUBSTITUTE($B6," ",""),CHAR(160),"")),--ISNUMBER(SEARCH("|CU->>F|","|"&IFERROR(LEFT(SUBSTITUTE(SUBSTITUTE(Operations!$F$4:$F$67," ",""),CHAR(160),""),FIND(":",SUBSTITUTE(SUBSTITUTE(Operations!$F$4:$F$67," ",""),CHAR(160),""))-1),"")&"|")))>0,"trovato","non trovato")} -> trovato

Sheet catalogo-ssu_to_cu
B1: Operation | C1: Check
B2: instance_descriptor | C2: {=IF(SUMPRODUCT(--(IFERROR(MID(SUBSTITUTE(SUBSTITUTE(Operations!$F$4:$F$67," ",""),CHAR(160),""),FIND(":",SUBSTITUTE(SUBSTITUTE(Operations!$F$4:$F$67," ",""),CHAR(160),""))+1,999),"")=SUBSTITUTE(SUBSTITUTE($B2," ",""),CHAR(160),"")),--ISNUMBER(SEARCH("|CU->>C|","|"&IFERROR(LEFT(SUBSTITUTE(SUBSTITUTE(Operations!$F$4:$F$67," ",""),CHAR(160),""),FIND(":",SUBSTITUTE(SUBSTITUTE(Operations!$F$4:$F$67," ",""),CHAR(160),""))-1),"")&"|")))>0,"trovato","non trovato")} -> trovato

Sheet bo_to_ri
B1: Operation | C1: Check
B2: send_instance | C2: {=IF(SUMPRODUCT(--(IFERROR(MID(SUBSTITUTE(SUBSTITUTE(Operations!$G$4:$G$67," ",""),CHAR(160),""),FIND(":",SUBSTITUTE(SUBSTITUTE(Operations!$G$4:$G$67," ",""),CHAR(160),""))+1,999),"")=SUBSTITUTE(SUBSTITUTE($B2," ",""),CHAR(160),"")),--ISNUMBER(SEARCH("|RI->>B|","|"&IFERROR(LEFT(SUBSTITUTE(SUBSTITUTE(Operations!$G$4:$G$67," ",""),CHAR(160),""),FIND(":",SUBSTITUTE(SUBSTITUTE(Operations!$G$4:$G$67," ",""),CHAR(160),""))-1),"")&"|")))>0,"trovato","non trovato")} -> trovato
B3: retry | C3: {=IF(SUMPRODUCT(--(IFERROR(MID(SUBSTITUTE(SUBSTITUTE(Operations!$G$4:$G$67," ",""),CHAR(160),""),FIND(":",SUBSTITUTE(SUBSTITUTE(Operations!$G$4:$G$67," ",""),CHAR(160),""))+1,999),"")=SUBSTITUTE(SUBSTITUTE($B3," ",""),CHAR(160),"")),--ISNUMBER(SEARCH("|RI->>B|","|"&IFERROR(LEFT(SUBSTITUTE(SUBSTITUTE(Operations!$G$4:$G$67," ",""),CHAR(160),""),FIND(":",SUBSTITUTE(SUBSTITUTE(Operations!$G$4:$G$67," ",""),CHAR(160),""))-1),"")&"|")))>0,"trovato","non trovato")} -> trovato
B4: notify_receipt | C4: {=IF(SUMPRODUCT(--(IFERROR(MID(SUBSTITUTE(SUBSTITUTE(Operations!$G$4:$G$67," ",""),CHAR(160),""),FIND(":",SUBSTITUTE(SUBSTITUTE(Operations!$G$4:$G$67," ",""),CHAR(160),""))+1,999),"")=SUBSTITUTE(SUBSTITUTE($B4," ",""),CHAR(160),"")),--ISNUMBER(SEARCH("|RI->>B|","|"&IFERROR(LEFT(SUBSTITUTE(SUBSTITUTE(Operations!$G$4:$G$67," ",""),CHAR(160),""),FIND(":",SUBSTITUTE(SUBSTITUTE(Operations!$G$4:$G$67," ",""),CHAR(160),""))-1),"")&"|")))>0,"trovato","non trovato")} -> trovato
B5: instance/{cui_uuid}/document/{resource_id} | C5: {=IF(SUMPRODUCT(--(IFERROR(MID(SUBSTITUTE(SUBSTITUTE(Operations!$G$4:$G$67," ",""),CHAR(160),""),FIND(":",SUBSTITUTE(SUBSTITUTE(Operations!$G$4:$G$67," ",""),CHAR(160),""))+1,999),"")=SUBSTITUTE(SUBSTITUTE($B5," ",""),CHAR(160),"")),--ISNUMBER(SEARCH("|RI->>B|","|"&IFERROR(LEFT(SUBSTITUTE(SUBSTITUTE(Operations!$G$4:$G$67," ",""),CHAR(160),""),FIND(":",SUBSTITUTE(SUBSTITUTE(Operations!$G$4:$G$67," ",""),CHAR(160),""))-1),"")&"|")))>0,"trovato","non trovato")} -> trovato

Sheet catalogo-ssu_to_ri
B1: Operation | C1: Check
B2: instance_descriptor | C2: {=IF(SUMPRODUCT(--(IFERROR(MID(SUBSTITUTE(SUBSTITUTE(Operations!$G$4:$G$67," ",""),CHAR(160),""),FIND(":",SUBSTITUTE(SUBSTITUTE(Operations!$G$4:$G$67," ",""),CHAR(160),""))+1,999),"")=SUBSTITUTE(SUBSTITUTE($B2," ",""),CHAR(160),"")),--ISNUMBER(SEARCH("|RI->>C|","|"&IFERROR(LEFT(SUBSTITUTE(SUBSTITUTE(Operations!$G$4:$G$67," ",""),CHAR(160),""),FIND(":",SUBSTITUTE(SUBSTITUTE(Operations!$G$4:$G$67," ",""),CHAR(160),""))-1),"")&"|")))>0,"trovato","non trovato")} -> trovato
B3: request_cui | C3: {=IF(SUMPRODUCT(--(IFERROR(MID(SUBSTITUTE(SUBSTITUTE(Operations!$G$4:$G$67," ",""),CHAR(160),""),FIND(":",SUBSTITUTE(SUBSTITUTE(Operations!$G$4:$G$67," ",""),CHAR(160),""))+1,999),"")=SUBSTITUTE(SUBSTITUTE($B3," ",""),CHAR(160),"")),--ISNUMBER(SEARCH("|RI->>C|","|"&IFERROR(LEFT(SUBSTITUTE(SUBSTITUTE(Operations!$G$4:$G$67," ",""),CHAR(160),""),FIND(":",SUBSTITUTE(SUBSTITUTE(Operations!$G$4:$G$67," ",""),CHAR(160),""))-1),"")&"|")))>0,"trovato","non trovato")} -> trovato
B4: audit | C4: {=IF(SUMPRODUCT(--(IFERROR(MID(SUBSTITUTE(SUBSTITUTE(Operations!$G$4:$G$67," ",""),CHAR(160),""),FIND(":",SUBSTITUTE(SUBSTITUTE(Operations!$G$4:$G$67," ",""),CHAR(160),""))+1,999),"")=SUBSTITUTE(SUBSTITUTE($B4," ",""),CHAR(160),"")),--ISNUMBER(SEARCH("|RI->>C|","|"&IFERROR(LEFT(SUBSTITUTE(SUBSTITUTE(Operations!$G$4:$G$67," ",""),CHAR(160),""),FIND(":",SUBSTITUTE(SUBSTITUTE(Operations!$G$4:$G$67," ",""),CHAR(160),""))-1),"")&"|")))>0,"trovato","non trovato")} -> trovato
